15.01.2020 05:09:40:5314 PmsManager------>PmsMgr : GeneralUtils, 1.0.2.0: Starting listening on port: 5001
__________________________

15.01.2020 05:09:43:7680 AmadeoServ------>OnStart : GeneralUtils, 1.0.2.0: Service Properly started v1.9.9.0
__________________________

15.01.2020 20:04:09:5347 DataAccessLayer------>ExecuteQuery : GeneralUtils, 1.0.2.0:    at System.Data.Entity.Core.EntityClient.EntityConnection.<OpenAsync>d__8.MoveNext()
--- End of stack trace from previous location where exception was thrown ---
   at System.Runtime.ExceptionServices.ExceptionDispatchInfo.Throw()
   at System.Runtime.CompilerServices.TaskAwaiter.HandleNonSuccessAndDebuggerNotification(Task task)
   at System.Data.Entity.Core.Objects.ObjectContext.<EnsureConnectionAsync>d__9.MoveNext()
--- End of stack trace from previous location where exception was thrown ---
   at System.Runtime.ExceptionServices.ExceptionDispatchInfo.Throw()
   at System.Runtime.CompilerServices.TaskAwaiter.HandleNonSuccessAndDebuggerNotification(Task task)
   at System.Data.Entity.Core.Objects.ObjectContext.<ExecuteInTransactionAsync>d__3d`1.MoveNext()
--- End of stack trace from previous location where exception was thrown ---
   at System.Runtime.ExceptionServices.ExceptionDispatchInfo.Throw()
   at System.Runtime.CompilerServices.TaskAwaiter.HandleNonSuccessAndDebuggerNotification(Task task)
   at System.Data.Entity.Utilities.TaskExtensions.CultureAwaiter`1.GetResult()
   at System.Data.Entity.Core.Objects.ObjectContext.<ExecuteStoreQueryReliablyAsync>d__6c`1.MoveNext()
--- End of stack trace from previous location where exception was thrown ---
   at System.Runtime.ExceptionServices.ExceptionDispatchInfo.Throw()
   at System.Runtime.CompilerServices.TaskAwaiter.HandleNonSuccessAndDebuggerNotification(Task task)
   at System.Data.Entity.Utilities.TaskExtensions.CultureAwaiter`1.GetResult()
   at System.Data.Entity.Internal.LazyAsyncEnumerator`1.<FirstMoveNextAsync>d__0.MoveNext()
--- End of stack trace from previous location where exception was thrown ---
   at System.Runtime.ExceptionServices.ExceptionDispatchInfo.Throw()
   at System.Runtime.CompilerServices.TaskAwaiter.HandleNonSuccessAndDebuggerNotification(Task task)
   at System.Data.Entity.Infrastructure.IDbAsyncEnumerableExtensions.<ForEachAsync>d__5`1.MoveNext()
--- End of stack trace from previous location where exception was thrown ---
   at System.Runtime.ExceptionServices.ExceptionDispatchInfo.Throw()
   at System.Runtime.CompilerServices.TaskAwaiter.HandleNonSuccessAndDebuggerNotification(Task task)
   at DALRepository.Context.IntegraContext.B}3p>3\.II\\"rsfj3 `=Thn!A$`1.MoveNext()
__________________________

15.01.2020 20:04:10:1986 ServiceScheduler------>RunCheckInOuts : GeneralUtils, 1.0.2.0: Object reference not set to an instance of an object.
__________________________


------>